Workbook

Sheet Sheet1
A1: Ref | B1: db_percent_ID | C1: Common_name | D1: Species_name | E1: Category | F1: Kingdom | G1: Phylum | H1: Class | I1: Order | J1: Family | K1: Genus | L1: species | M1: PhylogenySorting
A2: >1.00_Sturgeon_sp_Acipenser_sp | B2: 100 | C2: Sturgeon sp | D2: Acipenser sp | E2: Teleost Fish | F2: Animalia | G2: Chordata | H2: Actinopterygii | I2: Acipenseriformes | J2: Acipenseridae | K2: Acipenser | M2: =_xlfn.XLOOKUP(I2,'phylogeny lookup'!A:A,'phylogeny lookup'!B:B) -> T03
A3: >2.00_Wood_duck_Aix_sponsa | B3: 100 | C3: Wood duck | D3: Aix sponsa | E3: Bird | F3: Animalia | G3: Chordata | H3: Aves | I3: Anseriformes | J3: Anatidae | K3: Aix | L3: sponsa
A4: >2.00_Razorbill_Alca_torda | B4: 100 | C4: Razorbill | D4: Alca torda | E4: Bird | F4: Animalia | G4: Chordata | H4: Aves | I4: Charadriiformes | J4: Alcidae | K4: Alca | L4: torda
A5: >2.00_Chukar_partridge_Alectoris_chukar | B5: 100 | C5: Chukar partridge | D5: Alectoris chukar | E5: Bird | F5: Animalia | G5: Chordata | H5: Aves | I5: Galliformes | J5: Phasianidae | K5: Alectoris | L5: chukar
A6: >2.00_Little_auk_Alle_alle | B6: 100 | C6: Little auk | D6: Alle alle | E6: Bird | F6: Animalia | G6: Chordata | H6: Aves | I6: Charadriiformes | J6: Alcidae | K6: Alle | L6: alle
A7: >1.01_Thresher_shark_Alopias_vulpinus | B7: 100 | C7: Thresher shark | D7: Alopias vulpinus | E7: Elasmobranch | F7: Animalia | G7: Chordata | H7: Chondrichthyes | I7: Lamniformes | J7: Alopiidae | K7: Alopias | L7: vulpinus | M7: =_xlfn.XLOOKUP(I7,'phylogeny lookup'!A:A,'phylogeny lookup'!B:B) -> E06
A8: >1.00_Orange_filefish_Aluterus_schoepfii | B8: 100 | C8: Orange filefish | D8: Aluterus schoepfii | E8: Teleost Fish | F8: Animalia | G8: Chordata | H8: Actinopterygii | I8: Tetraodontiformes | J8: Monacanthidae | K8: Aluterus | L8: schoepfii | M8: =_xlfn.XLOOKUP(I8,'phylogeny lookup'!A:A,'phylogeny lookup'!B:B) -> T40
A9: >1.00_Rock_bass_Ambloplites_rupestris | B9: 100 | C9: Rock bass | D9: Ambloplites rupestris | E9: Teleost Fish | F9: Animalia | G9: Chordata | H9: Actinopterygii | I9: Centrarchiformes | J9: Centrarchidae | K9: Ambloplites | L9: rupestris | M9: =_xlfn.XLOOKUP(I9,'phylogeny lookup'!A:A,'phylogeny lookup'!B:B) -> T58
A10: >1.01_Thorny_skate_Amblyraja_radiata_OR_arctic_or_antarctic_skate_Amblyraja_spp | B10: 100 | C10: Thorny skate or Arctic or Antarctic skate | D10: Amblyraja radiata or Amblyraja spp | E10: Elasmobranch | F10: Animalia | G10: Chordata | H10: Chondrichthyes | I10: Rajiformes | J10: Rajidae | K10: Amblyraja | M10: =_xlfn.XLOOKUP(I10,'phylogeny lookup'!A:A,'phylogeny lookup'!B:B) -> E10
A11: >1.00_White_catfish_Ameiurus_catus | B11: 100 | C11: White catfish | D11: Ameiurus catus | E11: Teleost Fish | F11: Animalia | G11: Chordata | H11: Actinopterygii | I11: Siluriformes | J11: Ictaluridae | K11: Ameiurus | L11: catus | M11: =_xlfn.XLOOKUP(I11,'phylogeny lookup'!A:A,'phylogeny lookup'!B:B) -> T17
A12: >1.00_Yellow_bullhead_Ameiurus_natalis | B12: 100 | C12: Yellow bullhead | D12: Ameiurus natalis | E12: Teleost Fish | F12: Animalia | G12: Chordata | H12: Actinopterygii | I12: Siluriformes | J12: Ictaluridae | K12: Ameiurus | L12: natalis | M12: =_xlfn.XLOOKUP(I12,'phylogeny lookup'!A:A,'phylogeny lookup'!B:B) -> T17
A13: >1.00_Brown_bullhead_Ameiurus_nebulosus | B13: 100 | C13: Brown bullhead | D13: Ameiurus nebulosus | E13: Teleost Fish | F13: Animalia | G13: Chordata | H13: Actinopterygii | I13: Siluriformes | J13: Ictaluridae | K13: Ameiurus | L13: nebulosus | M13: =_xlfn.XLOOKUP(I13,'phylogeny lookup'!A:A,'phylogeny lookup'!B:B) -> T17
A14: >1.00_Brown_bullhead99_Ameiurus_nebulosus99 | B14: 99 | C14: Brown bullhead | D14: Ameiurus nebulosus | E14: Teleost Fish | F14: Animalia | G14: Chordata | H14: Actinopterygii | I14: Siluriformes | J14: Ictaluridae | K14: Ameiurus | L14: nebulosus | M14: =_xlfn.XLOOKUP(I14,'phylogeny lookup'!A:A,'phylogeny lookup'!B:B) -> T17
A15: >1.00_American_sand_lance_Ammodytes_americanus | B15: 100 | C15: American sand lance | D15: Ammodytes americanus | E15: Teleost Fish | F15: Animalia | G15: Chordata | H15: Actinopterygii | I15: Labriformes | J15: Ammodytidae | K15: Ammodytes | L15: americanus | M15: =_xlfn.XLOOKUP(I15,'phylogeny lookup'!A:A,'phylogeny lookup'!B:B) -> T49
A16: >1.00_Northern_sand_lance_Ammodytes_dubius | B16: 100 | C16: Northern sand lance | D16: Ammodytes dubius | E16: Teleost Fish | F16: Animalia | G16: Chordata | H16: Actinopterygii | I16: Labriformes | J16: Ammodytidae | K16: Ammodytes | L16: dubius | M16: =_xlfn.XLOOKUP(I16,'phylogeny lookup'!A:A,'phylogeny lookup'!B:B) -> T49
A17: >1.00_Climbing_perch_Anabas_testudineus | B17: 100 | C17: Climbing perch | D17: Anabas testudineus | E17: Teleost Fish | F17: Animalia | G17: Chordata | H17: Actinopterygii | I17: Anabantiformes | J17: Anabantidae | K17: Anabas | L17: testudineus | M17: =_xlfn.XLOOKUP(I17,'phylogeny lookup'!A:A,'phylogeny lookup'!B:B) -> T50
A18: >1.00_Atlantic_wolffish_Anarhichas_lupus | B18: 100 | C18: Atlantic wolffish | D18: Anarhichas lupus | E18: Teleost Fish | F18: Animalia | G18: Chordata | H18: Actinopterygii | I18: Perciformes | J18: Anarhichadidae | K18: Anarhichas | L18: lupus | M18: =_xlfn.XLOOKUP(I18,'phylogeny lookup'!A:A,'phylogeny lookup'!B:B) -> T60
A19: >2.00_Mallard_other_Anas_sp | B19: 100 | C19: Mallard sp | D19: Anas sp | E19: Bird | F19: Animalia | G19: Chordata | H19: Aves | I19: Anseriformes | J19: Anatidae | K19: Anas
A20: >2.00_Canada_goose_other_geese_swans | B20: 100 | C20: Duck geese or swan | D20: Anatidae sp | E20: Bird | F20: Animalia | G20: Chordata | H20: Aves | I20: Anseriformes | J20: Anatidae
A21: >2.00_American_or_fowlers_toad_Anaxyrus_americanus_fowleri | B21: 100 | C21: American or fowlers toad | D21: Anaxyrus americanus or fowleri | E21: Amphibian | F21: Animalia | G21: Chordata | H21: Amphibia | I21: Anura | J21: Bufonidae | K21: Anaxyrus
A22: >2.00_Fowlers_toad_Anaxyrus_fowleri | B22: 100 | C22: Fowlers toad | D22: Anaxyrus fowleri | E22: Amphibian | F22: Animalia | G22: Chordata | H22: Amphibia | I22: Anura | J22: Bufonidae | K22: Anaxyrus | L22: fowleri
A23: >2.00_Southern_toad_Anaxyrus_terrestris | B23: 100 | C23: Southern toad | D23: Anaxyrus terrestris | E23: Amphibian | F23: Animalia | G23: Chordata | H23: Amphibia | I23: Anura | J23: Bufonidae | K23: Anaxyrus | L23: terrestris
A24: >1.00_Broad_striped_anchovy_Anchoa_hepsetus | B24: 100 | C24: Broad striped anchovy | D24: Anchoa hepsetus | E24: Teleost Fish | F24: Animalia | G24: Chordata | H24: Actinopterygii | I24: Clupeiformes | J24: Engraulidae | K24: Anchoa | L24: hepsetus | M24: =_xlfn.XLOOKUP(I24,'phylogeny lookup'!A:A,'phylogeny lookup'!B:B) -> T13
A25: >1.00_Shortfinger_anchovy_Anchoa_lyolepis | B25: 100 | C25: Shortfinger anchovy | D25: Anchoa lyolepis | E25: Teleost Fish | F25: Animalia | G25: Chordata | H25: Actinopterygii | I25: Clupeiformes | J25: Engraulidae | K25: Anchoa | L25: lyolepis | M25: =_xlfn.XLOOKUP(I25,'phylogeny lookup'!A:A,'phylogeny lookup'!B:B) -> T13
A26: >1.00_Bay_anchovy_Anchoa_mitchilli | B26: 100 | C26: Bay anchovy | D26: Anchoa mitchilli | E26: Teleost Fish | F26: Animalia | G26: Chordata | H26: Actinopterygii | I26: Clupeiformes | J26: Engraulidae | K26: Anchoa | L26: mitchilli | M26: =_xlfn.XLOOKUP(I26,'phylogeny lookup'!A:A,'phylogeny lookup'!B:B) -> T13
A27: >1.10_Bay_anchovy99a_Anchoa_mitchilli99a | B27: 99 | C27: Bay anchovy | D27: Anchoa mitchilli | E27: Teleost Fish | F27: Animalia | G27: Chordata | H27: Actinopterygii | I27: Clupeiformes | J27: Engraulidae | K27: Anchoa | L27: mitchilli | M27: =_xlfn.XLOOKUP(I27,'phylogeny lookup'!A:A,'phylogeny lookup'!B:B) -> T13
A28: >1.00_American_eel_Anguilla_rostrata | B28: 100 | C28: American eel | D28: Anguilla rostrata | E28: Teleost Fish | F28: Animalia | G28: Chordata | H28: Actinopterygii | I28: Anguilliformes | J28: Anguillidae | K28: Anguilla | L28: rostrata | M28: =_xlfn.XLOOKUP(I28,'phylogeny lookup'!A:A,'phylogeny lookup'!B:B) -> T11
A29: >1.00_Fourspine_stickleback_Apeltes_quadracus | B29: 100 | C29: Fourspine stickleback | D29: Apeltes quadracus | E29: Teleost Fish | F29: Animalia | G29: Chordata | H29: Actinopterygii | I29: Perciformes | J29: Gasterosteidae | K29: Apeltes | L29: quadracus | M29: =_xlfn.XLOOKUP(I29,'phylogeny lookup'!A:A,'phylogeny lookup'!B:B) -> T60
A30: >2.00_Great_Shearwater_Ardenna_gravis | B30: 100 | C30: Great Shearwater | D30: Ardenna gravis | E30: Bird | F30: Animalia | G30: Chordata | H30: Aves | I30: Procellariiformes | J30: Procellariidae | K30: Ardenna | L30: gravis
A31: >2.00_shearwater_Puffinus_species_sooty_shearwater_Puffinus_griseus_OR_great_shearwater_Puffinus_gravis_shortRef | B31: 100 | C31: Great or Sooty shearwater | D31: Ardenna griseus or Ardenna gravis | E31: Bird | F31: Animalia | G31: Chordata | H31: Aves | I31: Procellariiformes | J31: Procellariidae | K31: Ardenna
A32: >1.00_Greater_argentine_Argentina_silus | B32: 100 | C32: Greater argentine | D32: Argentina silus | E32: Teleost Fish | F32: Animalia | G32: Chordata | H32: Actinopterygii | I32: Argentiniformes | J32: Argentinidae | K32: Argentina | L32: silus | M32: =_xlfn.XLOOKUP(I32,'phylogeny lookup'!A:A,'phylogeny lookup'!B:B) -> T19
A33: >1.10_Greater_argentine_Argentina_silus | B33: 100 | C33: Greater argentine | D33: Argentina silus | E33: Teleost Fish | F33: Animalia | G33: Chordata | H33: Actinopterygii | I33: Argentiniformes | J33: Argentinidae | K33: Argentina | L33: silus | M33: =_xlfn.XLOOKUP(I33,'phylogeny lookup'!A:A,'phylogeny lookup'!B:B) -> T19
A34: >1.00_silver_rag_driftfish_Ariomma_bondi_OR_other_Ariomma_spp | B34: 100 | C34: Driftfish sp | D34: Ariomma bondi or other Ariomma spp | E34: Teleost Fish | F34: Animalia | G34: Chordata | H34: Actinopterygii | I34: Scombriformes | J34: Ariommatidae | K34: Ariomma | M34: =_xlfn.XLOOKUP(I34,'phylogeny lookup'!A:A,'phylogeny lookup'!B:B) -> T52
A35: >1.00_Northern_stargazer | B35: 100 | C35: Northern stargazer | D35: Astroscopus guttatus | E35: Teleost Fish | F35: Animalia | G35: Chordata | H35: Actinopterygii | I35: Perciformes | J35: Uranoscopidae | K35: Astroscopus | L35: guttatus | M35: =_xlfn.XLOOKUP(I35,'phylogeny lookup'!A:A,'phylogeny lookup'!B:B) -> T60
A36: >2.00_Duck_sp_Athya_sp | B36: 100 | C36: Duck sp | D36: Aythya sp | E36: Bird | F36: Animalia | G36: Chordata | H36: Aves | I36: Anseriformes | J36: Anatidae | K36: Aythya
A37: >2.00_Duck_sp_athya_sp98 | B37: 98 | C37: Duck sp | D37: Aythya sp | E37: Bird | F37: Animalia | G37: Chordata | H37: Aves | I37: Anseriformes | J37: Anatidae | K37: Aythya
A38: >1.00_Silver_perch_Bairdiella_chrysoura | B38: 100 | C38: Silver perch | D38: Bairdiella chrysoura | E38: Teleost Fish | F38: Animalia | G38: Chordata | H38: Actinopterygii | I38: Acanthuriformes | J38: Sciaenidae | K38: Bairdiella | L38: chrysoura | M38: =_xlfn.XLOOKUP(I38,'phylogeny lookup'!A:A,'phylogeny lookup'!B:B) -> T38
A39: >2.00_Minke_whale_Balaenoptera_acutorostrata | B39: 100 | C39: Minke whale | D39: Balaenoptera acutorostrata | E39: Marine Mammal | F39: Animalia | G39: Chordata | H39: Mammalia | I39: Artiodactyla | J39: Balaenopteridae | K39: Balaenoptera | L39: acutorostrata
A40: >2.00_Sei_whale_Balaenoptera_borealis_NC_006929.1 | B40: 100 | C40: Sei whale | D40: Balaenoptera borealis | E40: Marine Mammal | F40: Animalia | G40: Chordata | H40: Mammalia | I40: Artiodactyla | J40: Balaenopteridae | K40: Balaenoptera | L40: borealis
...

Sheet phylogeny lookup
A1: Order | B1: Rank
A2: Hexanchiformes | B2: E01
A3: Squaliformes | B3: E02
A4: Pristiophoriformes | B4: E03
A5: Squatiniformes | B5: E04
A6: Orectolobiformes | B6: E05
A7: Lamniformes | B7: E06
A8: Carcharhiniformes | B8: E07
A9: Torpediniformes | B9: E08
A10: Rhinopristiformes | B10: E09
A11: Rajiformes | B11: E10
A12: Myliobatiformes | B12: E11
... A72: Perciformes | B72: T60

Sheet formatted seq
A1: >1.00_Acadian_redfish_Sebastes_fasciatus | B1: ACTATGCCTAGCCCTAAACCTTGGTAACATATCACATACCCTACCCGCCTGGGAACTACGAGCACCAGCTTAAAACCCAAAGGACTTGGCGGTGCTTTAGACCCCC
A2: >1.00_Agujon_needlefish_Tylosurus_acus | B2: ACTATGCACAGCCCTAAACTTTGATAGAAACATTACACCCACTATCCGCCAGGGTACTACGAGCTCTAGCTTAAAATCCAAAGGACTTGGCGGTGCTTTAGACCCAC
A3: >1.00_American_anglerfish_Lophius_americanus | B3: ACTATGCCTAGCCCTAAACATTGGCAACACAAAACACCCGTTGCCCGCCAGGGCACTACGAGCATTAGCTTAAAACCCAAAGGACTTGGCGGTGCTTTAGACCCAC
A4: >1.00_American_butterfish_Peprilus_triacanthus | B4: ACTATGCTTAGCCGTAAACATTGATAGAGATTTACACCTTCTATCCGCCTGGGAACTACGAGCATTAGCTTAAAACCCAAAGGACTTGGCGGTACTTTAGATCCCC
A5: >1.00_American_conger_Conger_oceanicus | B5: ACTATGCTTAACTGTAAACAAAGATGATAATACACAAACATCATCCGCCAGGGGATTACGAGCAAAGTTTAAAACCCAAAGGACTTGGCGGTGCCTCAAACCCAC
A6: >1.00_American_eel_Anguilla_rostrata | B6: ACTATGCTCAACCTTAAACAACGATGACAACATACAAATATCATCCGCCAGGGGACTACGAGCGTTAGCTTAAAACCCAAAGGACTTGGCGGTGCCTCAAACCCAC
A7: >1.00_American_gizzard_shad_Dorosoma_cepedianum | B7: ACTATGCCCTGCCGTAAACTTAGATATTTCAATACAACAAATATCCGCCCGGGGACTACGAGCGCCAGCTTAAAACCCAAAGGACTTGGCGGTGCTTCAGACCCCC
A8: >1.00_American_sand_lance_Ammodytes_americanus | B8: ACTATGCTTAGCCCTAAACATCGATAGCGCAATACACCTGCTATCCGCCTGGGAACTACGAGCATCAGCTTGAAACCCAAAGGACTTGGCGGTGCTTTAGATCCAC
A9: >1.00_American_plaice_Hippoglossoides_platessoides_also_matches_Winter_flounder_refseq | B9: ACTATGCTTAGCCCTAAACATCGATTGCACAATACACTCCATATCCGCCCGGGGATTATGAACGTCAGTTTAAAACCCAAAGGACTTGGCGGTGCTTAACATCCAC
A10: >1.00_Brook_trout_Salvelinus_fontinalis | B10: ACTATGCCTAGCCGTAAACTTTGATAGAAAAATACAACTGATATCCGCCAGGGAACTACAAGCGCCAGCTTAAAACCCAAAGGACTTGGCGGTGCCTCAGACCCAC
A11: >1.00_Armored_searobin_Peristedion_miniatum_or_radiated_shanny_Ulvaria_subbifurcata | B11: ACTATGCCTAGCCCTAAACATTGATAGTACCCTACACCCACTATCCGCCTGGGAACTACGAGCATCAGCTTGAAACCCAAAGGACTTGGCGGTGCTTTAGATCCAC
A12: >1.00_Asian_pencil_halfbeak99_Hyporhamphus_intermedius99 | B12: ACTATGCTCAGCCGTAAAATTTGATAGAATTCTACACCCACTATCCGCCAGGGAATTACGAGCACCAGCTTAAAACCCAAAGGACTTGGCGGTGCTTTAGACCCAC
... A524: >4.00_White_anemone_Diadumene_leucolena | B524: GGTAGTCCACACTGTGAACTCTGAAGATGATGCTTAGCAGACCCGAAAGGTTAAATCTTCCGCCTGAGTAGTACGATCGCAAGATTAAAATTCAAAAACTTTGGCTGTTCACTATTTCGA

Sheet FASTA
A1: >1.00_Acadian_redfish_Sebastes_fasciatus
A2: ACTATGCCTAGCCCTAAACCTTGGTAACATATCACATACCCTACCCGCCTGGGAACTACGAGCACCAGCTTAAAACCCAAAGGACTTGGCGGTGCTTTAGACCCCC
A3: >1.00_Agujon_needlefish_Tylosurus_acus
A4: ACTATGCACAGCCCTAAACTTTGATAGAAACATTACACCCACTATCCGCCAGGGTACTACGAGCTCTAGCTTAAAATCCAAAGGACTTGGCGGTGCTTTAGACCCAC
A5: >1.00_American_anglerfish_Lophius_americanus
A6: ACTATGCCTAGCCCTAAACATTGGCAACACAAAACACCCGTTGCCCGCCAGGGCACTACGAGCATTAGCTTAAAACCCAAAGGACTTGGCGGTGCTTTAGACCCAC
A7: >1.00_American_butterfish_Peprilus_triacanthus
A8: ACTATGCTTAGCCGTAAACATTGATAGAGATTTACACCTTCTATCCGCCTGGGAACTACGAGCATTAGCTTAAAACCCAAAGGACTTGGCGGTACTTTAGATCCCC
A9: >1.00_American_conger_Conger_oceanicus
A10: ACTATGCTTAACTGTAAACAAAGATGATAATACACAAACATCATCCGCCAGGGGATTACGAGCAAAGTTTAAAACCCAAAGGACTTGGCGGTGCCTCAAACCCAC
A11: >1.00_American_eel_Anguilla_rostrata
A12: ACTATGCTCAACCTTAAACAACGATGACAACATACAAATATCATCCGCCAGGGGACTACGAGCGTTAGCTTAAAACCCAAAGGACTTGGCGGTGCCTCAAACCCAC
... A1048: GGTAGTCCACACTGTGAACTCTGAAGATGATGCTTAGCAGACCCGAAAGGTTAAATCTTCCGCCTGAGTAGTACGATCGCAAGATTAAAATTCAAAAACTTTGGCTGTTCACTATTTCGA

Sheet ID codes
A1: Organism | B1: Code
A2: Fish | B2: 1
A3: Elasmobranch | B3: 1.01
A4: Alternative Fish Sequence | B4: 1.1
A5: Other Vertebrate (non human/pet) | B5: 2
A6: Pet/livestock | B6: 2.2
A7: Dog chromo | B7: 2.5
A8: Human mito | B8: 3
A9: Human chromo | B9: 3.5
A10: Invertebrate | B10: 4

Sheet update log
A1: Date | B1: update | C1: explanation | D1: Version
A2: 45303 | B2: white shark common named changed to bull shark | C2: Carcharhinus leucas was listed as white shark, the sequence matches Carcharhinus leucas which is bull shark
A3: 45344 | B3: tried to add Atlantic torpedo ray Tetronarce nobiliana | C3: no 12s reference
A4: 45344 | B4: corrected spellling on cunner genus to Tautogolabrus | C4: was Tetragolabrus
A5: 45344 | B5: corrected spelling on Apeltes quadricus | C5: was Apelties
A6: 45344 | B6: all of Jen's 12s additions from SBNMS were added after removing primers | C6: added and any duplicate sequences were removed
A7: 45345 | B7: dusky shark added
A8: 45345 | B8: smooth hammerhead added
A9: 45345 | B9: tiger shark added
A10: 45472 | B10: removed gaddidae 98 ref because we should get it by BLASTING at 98%
A11: 45538 | B11: scad98 sequence changed to round scad 100
A12: 45538 | B12: Remove L. guttatus 97% to replace with R. aurorubens
A13: 45538 | B13: Remove L. guttatus 98% to replace with Ocyurus chrysurus
A14: 45539 | B14: removed unknown shark 96b
A15: 45539 | B15: removed atlantic silverside secondary "1.10" sequences | C15: they were all 99% identity and likely represent sequencing errors. We will still pick these up with our pipeline and the 100% sequence
A16: 45539 | B16: removed mummichog secondary "1.10" sequences | C16: same as above
A17: 45539 | B17: removed summer flounder and tautog secondary "1.10" sequences | C17: same as above
A18: 45539 | B18: removed Atlantic salmon secondary "1.20" sequence | C18: same as above
A19: 45539 | B19: removed eastern musk turtle | C19: only 83% query coverage
A20: 45539 | B20: removed glossy ibis | C20: incomplete sequence and rare in new england
A21: 45539 | B21: all yellow flags addressed
A22: 45539 | B22: Add variants of Sphyrna lewini from NCBI
A23: 45539 | B23: Add Liparis gibbus | D23: 2024v1
A24: 45817 | B24: Delete pacific worm eel entry and replace with new Atlantic worm eel spp (Myrophis punctatus) | C24: new sequence added to Genbank | D24: 2025v1
A25: 45817 | B25: update sequence in our db to be 100% to E. olmstedi instead of 99 to nigrum | C25: olmstedi sequenced added to Genbank | D25: 2025v1
A26: 45819 | B26: add Aix sponsa to GMGI db | D26: 2025v1
A27: 45819 | B27: changed Ophidion marginatum96 to O. robsini | D27: 2025v1
A28: 45819 | B28: added Plethodon cinereus | D28: 2025v1
A29: 45819 | B29: updated >2.00_Cormorant99 to be >2.00_Double_crested_Cormorant_Nannopterum_auritum | D29: 2025v1
A30: 45819 | B30: added >2.00_American_crow_other_corvids to sheet1 | D30: 2025v1
A31: 45819 | B31: updated >2.00_American_widgeon_or_Gadwall_or_Eurasian_wigeon to >2.00_Mareca_ducks | D31: 2025v1
A32: 45819 | B32: Added Bothus robinsi to db | D32: 2025v1
A33: 45819 | B33: Added Priacanthus arenatus to db | D33: 2025v1
A34: 45819 | B34: Added Ceratoscopelus maderensis to db | D34: 2025v1
A35: 45819 | B35: Added Semotilus corporalis to db | D35: 2025v1
A36: 45819 | B36: updated genus species name info for bullfrog or green frog | D36: 2025v1
A37: 45825 | B37: added Ctenogobius boleosoma to db | D37: 2025v1
... A82: 46027 | B82: updated GMGI db to include full length sequence from Petromyzon marinus | D82: 2026v1
A83: 46027 | B83: Add Caranx crysos; I thought we had done this already because it feels familiar, but maybe not | C83: did that above by changing ignobilis to crysos | D83: 2026v1
A84: 46027 | B84: Investigate Lutjanus peru vs campechanus | C84: added two references for Lutjanus campechanus, one of which replaced L. peru | D84: 2026v1
...

Sheet update requests
A1: Date | B1: Update description | C1: Update requester | D1: Project | E1: Update complete | F1: Sequence
A2: 45428 | B2: Delete pacific worm eel entry and replace with new Atlantic worm eel spp (Myrophis punctatus) | C2: Emma Strand | D2: OSW | E2: 45817
A3: 45428 | B3: Remove L. guttatus 97% to replace with R. aurorubens | C3: Emma Strand | D3: OSW | E3: 45538
A4: 45428 | B4: Add variants of Sphyrna lewini from NCBI | C4: Emma Strand | D4: OSW | E4: 45539
A5: 45428 | B5: Add menidia menidia variants from NCBI | C5: Emma Strand | D5: OSW | E5: NA
A6: 45428 | B6: Add Liparis gibbus | C6: Emma Strand | D6: OSW | E6: 45539
A7: 45428 | B7: Add Decapterus punctatus from NCBI (it's 100% to NCBI and 100% to GMGI trachurus trachurus) | C7: Emma Strand | D7: OSW | E7: 45539
A8: 45435 | B8: Look into yellow flags on Sheet1 tab | C8: Emma Strand | D8: OSW | E8: 45539
A9: 45588 | B9: update sequence in our db to be 100% to E. olmstedi instead of 99 to nigrum | C9: Emma Strand | D9: WB FPS | E9: 45817
A10: 45588 | B10: Ondatra zibethicus and Neogale vison 100% hits from NCBI and 100% match to the 99 percent ID O. zib GMGI ref (WB filter pore size dataset see note in samplereport_taxonomicID | C10: Emma Strand | D10: WB FPS | E10: 45819
A11: 45588 | B11: add M. puctatus to GMGI db | C11: Emma Strand | D11: WB FPS | E11: 45817
A12: 45588 | B12: add Aix sponsa to GMGI db | C12: Emma Strand | D12: WB FPS | E12: 45819
A13: 45588 | B13: update Lgibbosus to be Lepomis gibbosus or auritus | C13: Emma Strand | D13: WB FPS | E13: 45819
A14: 45588 | B14: add O. marginatum seq that hit from NCBI and review current entries in our db | C14: Emma Strand | D14: WB FPS | E14: 45819
A15: 45588 | B15: add entry for Anaxyrus americanus or fowleri | C15: Emma Strand | D15: WB FPS | E15: 45819
A16: 45588 | B16: add Plethodon cinereus | C16: Emma Strand | D16: WB FPS | E16: 45819
A17: 45687 | B17: >2.00_Cormorant99 is in the FASTA and formatted seq but not Sheet1 | C17: Emma Strand | D17: WB FPS | E17: 45819
... A78: 45708 | B78: Add Scomberesox saurus | C78: Emma Strand | D78: OSW Feb 2025 | E78: 45827
A79: 45820 | B79: Add Ctenogobius boleosoma to db | C79: Emma Strand | D79: Matt CGobler | E79: 45825 | F79: ACTATGCCTAGCCATAAACACAGGTGAATACATCACACCTATCACTTGCCCGGAAACTACGAGCCCCAGCTTAAAACCCAAAGGACTTGGCGGTGCTTTAGACCCAC
A80: 45820 | B80: Add Sphyraena borealis to db | C80: Emma Strand | D80: Matt CGobler | E80: 45825 | F80: ACTATGCTCAGCCCTAAACATTGATTGGACTCTACAACCCCAATCCGCCTGGGAATTACGAACATAAGTTTAAAACCCAAAGGACTTGGCGGTGCTTTATATCCCC
A81: 45839 | B81: Add Kajika albida White marlin to GMGI db | C81: Dylan Comb | D81: OSW | E81: 46027
A82: 45839 | B82: Add Lagocephalus laevigatus to the GMGI db | C82: Dylan Comb | D82: OSW | E82: 46027
A83: 45839 | B83: add Xyrichtys novacula to GMGI db… another one where I'll have more confidence if its in aug-sept | C83: Dylan Comb | D83: OSW | E83: 46027
A84: 45839 | B84: add (Gaidropsarus enis OR argentatus) sequence to the GMGI db… asv is ae7b3f24960e55209cb07e27cf6f9650 | C84: Dylan Comb | D84: OSW | E84: 46027 | F84: ACTATGTATGATTGTTAACATCGATGATTCAATACCCAAATCATCCGCCTGGGTAATACGAGCGCTAGCTTAAAATCCAAAGGACTTGGCGGTGCTTTAGACCCCC
A85: 45839 | B85: add Ophichthus cruentifer to GMGI db | C85: Dylan Comb | D85: OSW | E85: 46027
A86: 45839 | B86: Add Sphoeroides dorsalis | C86: Dylan Comb | D86: OSW | E86: 46027
A87: 45839 | B87: update GMGI db Caranx ignobilis 99 to caranx crysos 100 | C87: Dylan Comb | D87: OSW | E87: 46024
A88: 45839 | B88: update GMGI db from Carcharhinus brevipinna to Carcharhinus brevipinna OR limbatus | C88: Dylan Comb | D88: OSW | E88: 46027
A89: 45902 | B89: update GMGI db to include full length sequence from Petromyzon marinus | C89: Emma Strand | D89: YL2019 NOAA | E89: 46027 | F89: TTAGATACCCCGCTATGCCTGCCATAAATAAACAACCGTCGCCAGGGCACTACGAACAATCGTTTAAAACCCAAAGAACTTGACGGCACCCTAAACCCACCTAGAGGAGCC
A90: 45902 | B90: Add Caranx crysos; I thought we had done this already because it feels familiar, but maybe not | C90: Emma Strand | D90: YL2019 NOAA | E90: 46027 | F90: ACTATGCTTAGCCCTAAACATTGATCGTTTACTACATCAAACATCCGCCTGGGAATTACGAACATTAGTTTAAAACCCAAAGGACTTGGCGGTGCTTAACATCCAC
A91: 45903 | B91: Investigate Lutjanus peru vs campechanus | C91: Dylan Comb | D91: OSW | E91: 46027 | F91: ACTATGCCTAGCCATAAACATTGATAGCTAACTACACCCACTATCCGCCCGGGGACTACGAGCATCAGCTTGAAACCCAAAGGACTTGGCGGTGCTTTAGATCCAC
A92: 46021 | B92: change American or Pacific sand lance to American sand lance | C92: Tim O'Donnell | D92: INS2 | E92: 46024
A93: 46024 | B93: Review all orders and remove suborders | C93: Tim O'Donnell | D93: INS2 | E93: 46024
A94: 46027 | B94: Ensure all entry names match on Sheet1 and FASTA | C94: Tim O'Donnell | D94: INS2 | E94: 46027
A95: 46035 | B95: remove >1.20_Unknown_fish_Stiphodon_alcedo93. It is darter goby, which is already in db | C95: Tim O'Donnell | D95: NA | E95: 46035
